<?xml version="1.0"?>

<robot name = "galbot_s1" xmlns:xacro="http://www.ros.org/wiki/xacro">
  <!-- Vehicle Properties -->
  <xacro:property name="wheel_radius" value="0.08"/>
  <xacro:property name="wheel_length" value="0.03"/>
  <xacro:property name="M_PI" value="3.14159265359"/>
  <link
    name="base_link">
    <inertial>
      <origin
        xyz="0.00665345844009456 0.0284133803771548 0.131750822981255"
        rpy="0 0 0" />
      <mass
        value="112.803619660318" /> <!--value="112.803619660318"--> 
      <inertia
        ixx="3.11572886017857"
        ixy="1.55321524777232E-05"
        ixz="0.00110989400701751"
        iyy="2.95831732579536"
        iyz="2.9214542246616E-05"
        izz="5.74346000147586" />
    </inertial>
    <visual>
      <origin
        xyz="0 0 0"
        rpy="0 0 0" />
      <geometry>
        <mesh
          filename="file://$(find galbot_s1_v1_description)/meshes/base_link.STL" />
      </geometry>
      <material
        name="base_link_material">
        <color
          rgba="0.59 0.96 1.0 1" />
      </material>
    </visual>
    <collision>
      <origin
        xyz="0 0 0"
        rpy="0 0 0" />
      <geometry>
        <mesh
          filename="file://$(find galbot_s1_v1_description)/meshes/convex_hull/base_link_convex_hull.STL" />
      </geometry>
    </collision>
  </link>
  <link
    name="column_base_link">
    <inertial>
      <origin
        xyz="0.0771639985543352 0.0241903194915318 -0.424408706840011"
        rpy="0 0 0" />
      <mass
        value="132.501515800473" />
      <inertia
        ixx="7.42532666586207"
        ixy="0.0156350052736675"
        ixz="-0.0374284417593983"
        iyy="5.8885745554111"
        iyz="-0.111045604537635"
        izz="11.0278744479288" />
    </inertial>
    <visual>
      <origin
        xyz="0 0 0"
        rpy="0 0 0" />
      <geometry>
        <mesh
          filename="file://$(find galbot_s1_v1_description)/meshes/column_base_link2.STL" />
      </geometry>
      <material
        name="column_base_link_material">
        <color
          rgba="0.733 1.0 1.0 1" />
      </material>
    </visual>
    <collision>
      <origin
        xyz="0 0 0"
        rpy="0 0 0" />
      <geometry>
        <mesh
          filename="file://$(find galbot_s1_v1_description)/meshes/convex_hull/column_base_link2_convex_hull.STL" />
      </geometry>
    </collision>
  </link>
  <joint
    name="column_base_joint"
    type="fixed">
    <origin
      xyz="-0.0715 0 0.55441"
      rpy="0 0 0" />
    <parent
      link="base_link" />
    <child
      link="column_base_link" />
    <axis
      xyz="0 0 0" />
  </joint>
  <!-- IMU -->
  <joint name="imu_joint" type="fixed">
    <origin xyz="0 0 0" rpy="0 0 0" />
    <parent link="base_link"/>
    <child link="imu_link" />
  </joint>

  <link name="imu_link">
  </link>
  <joint type="fixed" name="scan_joint">
    <origin xyz="0.0 0 0.4" rpy="0 0 0"/>
    <child link="scan_link"/>
    <parent link="base_link"/>
    <axis xyz="0 1 0" rpy="0 0 0"/>
  </joint>

  <link name='scan_link'>
    <inertial>
      <mass value="1e-5"/>
      <origin xyz="0 0 0" rpy="0 0 0"/>
      <inertia
          ixx="1e-6" ixy="0" ixz="0"
          iyy="1e-6" iyz="0"
          izz="1e-6"
      />
    </inertial>
    <collision name='collision'>
      <origin xyz="0 0 0" rpy="0 0 0"/> 
      <geometry>
        <box size=".1 .1 .1"/>
      </geometry>
    </collision>

    <visual name='scan_link_visual'>
      <origin xyz="0 0 0" rpy="0 0 0"/>
      <geometry>
        <mesh filename = "file://$(find galbot_s1_v1_description)/meshes/lidar.dae"/>
      </geometry>
    </visual>

  </link>

  <gazebo reference="scan_link">
    <selfCollide>false</selfCollide>
    <mu1 value="0.05" />
    <mu2 value="0.05" />
  </gazebo>


  <link
    name="Wheel_1_direction_link">
    <inertial>
      <origin
        xyz="0.000212741711577119 0.0330648318190014 0.0675533979393401"
        rpy="0 0 0" />
      <mass
        value="2.13611778992749" />
      <inertia
        ixx="0.00374225819733162"
        ixy="-8.41639877291454E-06"
        ixz="2.66657358636494E-05"
        iyy="0.00413405478708104"
        iyz="0.00111306912747484"
        izz="0.00309941801326172" />
    </inertial>
    <visual>
      <origin
        xyz="0 0 0"
        rpy="0 0 0" />
      <geometry>
        <mesh
          filename="file://$(find galbot_s1_v1_description)/meshes/Wheel_1_direction_link.STL" />
      </geometry>
      <material
        name="">
        <color
          rgba="0.752941176470588 0.752941176470588 0.752941176470588 1" />
      </material>
    </visual>
    <collision>
      <origin
        xyz="0 0 0"
        rpy="0 0 0" />
      <geometry>
        <mesh
          filename="file://$(find galbot_s1_v1_description)/meshes/convex_hull/Wheel_1_direction_link_convex_hull.STL" />
      </geometry>
    </collision>
  </link>
  <joint
    name="Wheel_1_direction_joint"
    type="revolute">
    <origin
      xyz="0.247 -0.247 0.0535"
      rpy="0 0 0" />
    <parent
      link="base_link" />
    <child
      link="Wheel_1_direction_link" />
    <axis
      xyz="0 0 1" />
    <limit
      lower="-3.14"
      upper="3.14"
      effort="2000"
      velocity="20.0" />
  </joint>
  <link name="Wheel_1_drive_link">
    <inertial>
      <origin xyz="-0.000458 3.45e-05 0.000901" rpy="0 0 0"/>
      <mass value="1.57669"/>
      <inertia 
        ixx="0.00316" ixy="5.19e-06" ixz="-1.53e-05"
        iyy="0.00319" iyz="2.49e-06" izz="0.00479"/>
    </inertial>

    <visual>
      <origin xyz="0 0 0" rpy="0 0 0"/>
      <geometry>
        <mesh filename="file://$(find galbot_s1_v1_description)/meshes/Wheel_1_drive_link.STL"/>
      </geometry>
      <material name="wheel_material1">
        <color rgba="0.2 0.2 0.2 1"/> 
      </material>
    </visual>

    <collision>
      <origin xyz="0 0 0" rpy="0 0 0"/>
      <geometry>
        <mesh filename="file://$(find galbot_s1_v1_description)/meshes/convex_hull/Wheel_1_drive_link_convex_hull.STL"/>
      </geometry>

      <geometry>
        <cylinder radius="${wheel_radius}" length="${wheel_length}"/>  
      </geometry>


      <surface>
        <contact>
          <ode>
            <kp>1e7</kp>
            <kd>0.5</kd>
            <max_vel>0.1</max_vel>
            <min_depth>0.001</min_depth>
          </ode>
        </contact>
        <friction>
          <ode>
            <mu>1.2</mu>
            <mu2>1.2</mu2>
          </ode>
        </friction>
      </surface>
    </collision>
  </link>
  <joint
    name="Wheel_1_drive_joint"
    type="continuous">
    <origin
      xyz="0 0 0"
      rpy="-1.5707963267949 0 0" />
    <parent
      link="Wheel_1_direction_link" />
    <child
      link="Wheel_1_drive_link" />
    <axis
      xyz="0 0 1" />
    <limit
      lower="-3.14"
      upper="3.14"
      effort="2000"
      velocity="100.0" />
  </joint>
  <link
    name="Wheel_2_direction_link">
    <inertial>
      <origin
        xyz="-0.000212741709548853 -0.0330648318136589 0.0675533979395656"
        rpy="0 0 0" />
      <mass
        value="2.13611778951419" />
      <inertia
        ixx="0.00374225819654317"
        ixy="-8.4163989404898E-06"
        ixz="-2.66657362454048E-05"
        iyy="0.00413405478620865"
        iyz="-0.00111306912725171"
        izz="0.0030994180129367" />
    </inertial>
    <visual>
      <origin
        xyz="0 0 0"
        rpy="0 0 0" />
      <geometry>
        <mesh
          filename="file://$(find galbot_s1_v1_description)/meshes/Wheel_2_direction_link.STL" />
      </geometry>
      <material
        name="">
        <color
          rgba="0.752941176470588 0.752941176470588 0.752941176470588 1" />
      </material>
    </visual>
    <collision>
      <origin
        xyz="0 0 0"
        rpy="0 0 0" />
      <geometry>
        <mesh
          filename="file://$(find galbot_s1_v1_description)/meshes/convex_hull/Wheel_2_direction_link_convex_hull.STL" />
      </geometry>
    </collision>
  </link>
  <joint
    name="Wheel_2_direction_joint"
    type="revolute">
    <origin
      xyz="0.247 0.247 0.0535"
      rpy="0 0 0" />
    <parent
      link="base_link" />
    <child
      link="Wheel_2_direction_link" />
    <axis
      xyz="0 0 1" />
    <limit
      lower="-3.14"
      upper="3.14"
      effort="2000"
      velocity="20.0" />
  </joint>
  <link
    name="Wheel_2_drive_link">
    <inertial>
      <origin
        xyz="-0.000458990547805488 1.86960746541009E-05 -0.000901214919732829"
        rpy="0 0 0" />
      <mass
        value="1.57669100389891" />
      <inertia
        ixx="0.00316177237127372"
        ixy="-1.46947143097995E-06"
        ixz="1.55292214158619E-05"
        iyy="0.00319453091266819"
        iyz="7.02742633414887E-07"
        izz="0.00479197119121216" />
    </inertial>
    <visual>
      <origin
        xyz="0 0 0"
        rpy="0 0 0" />
      <geometry>
        <mesh
          filename="file://$(find galbot_s1_v1_description)/meshes/Wheel_2_drive_link.STL" />
      </geometry>
      <material name="wheel_material2">
        <color rgba="0.2 0.2 0.2 1"/> 
      </material>
    </visual>
    <collision>
      <origin
        xyz="0 0 0"
        rpy="0 0 0" />
      <geometry>
        <mesh
          filename="file://$(find galbot_s1_v1_description)/meshes/convex_hull/Wheel_2_drive_link_convex_hull.STL" />
      </geometry>
      <geometry>
        <cylinder radius="${wheel_radius}" length="${wheel_length}"/>    
      </geometry>


      <surface>
        <contact>
          <ode>
            <kp>1e7</kp>
            <kd>0.5</kd>
            <max_vel>0.1</max_vel>
            <min_depth>0.001</min_depth>
          </ode>
        </contact>
        <friction>
          <ode>
            <mu>1.2</mu>
            <mu2>1.2</mu2>
          </ode>
        </friction>
      </surface>
    </collision>
  </link>
  <joint
    name="Wheel_2_drive_joint"
    type="continuous">
    <origin
      xyz="0 0 0"
      rpy="-1.5707963267949 0 0" />
    <parent
      link="Wheel_2_direction_link" />
    <child
      link="Wheel_2_drive_link" />
    <axis
      xyz="0 0 1" />
    <limit
      effort="2000"
      velocity="100.0" />
  </joint>
  <link
    name="Wheel_3_direction_link">
    <inertial>
      <origin
        xyz="0.000212741711821424 0.0330648318157447 0.0675533979397675"
        rpy="0 0 0" />
      <mass
        value="2.13611778964183" />
      <inertia
        ixx="0.00374225819682536"
        ixy="-8.41639885894748E-06"
        ixz="2.66657360141732E-05"
        iyy="0.00413405478668347"
        iyz="0.00111306912731889"
        izz="0.00309941801302034" />
    </inertial>
    <visual>
      <origin
        xyz="0 0 0"
        rpy="0 0 0" />
      <geometry>
        <mesh
          filename="file://$(find galbot_s1_v1_description)/meshes/Wheel_3_direction_link.STL" />
      </geometry>
      <material
        name="">
        <color
          rgba="0.752941176470588 0.752941176470588 0.752941176470588 1" />
      </material>
    </visual>
    <collision>
      <origin
        xyz="0 0 0"
        rpy="0 0 0" />
      <geometry>
        <mesh
          filename="file://$(find galbot_s1_v1_description)/meshes/convex_hull/Wheel_3_direction_link_convex_hull.STL" />
      </geometry>
    </collision>
  </link>
  <joint
    name="Wheel_3_direction_joint"
    type="revolute">
    <origin
      xyz="-0.247 -0.247 0.0535"
      rpy="0 0 0" />
    <parent
      link="base_link" />
    <child
      link="Wheel_3_direction_link" />
    <axis
      xyz="0 0 1" />
    <limit
      lower="-3.14"
      upper="3.14"
      effort="1000"
      velocity="20.0" />
  </joint>
  <link
    name="Wheel_3_drive_link">
    <inertial>
      <origin
        xyz="6.46723376635794E-05 -0.000454794225382665 0.000901210523079177"
        rpy="0 0 0" />
      <mass
        value="1.57669089927853" />
      <inertia
        ixx="0.00319449386482197"
        ixy="1.83141233948538E-06"
        ixz="8.59452979941066E-07"
        iyy="0.0031618087583676"
        iyz="-1.55211300002253E-05"
        izz="0.00479197073806869" />
    </inertial>
    <visual>
      <origin
        xyz="0 0 0"
        rpy="0 0 0" />
      <geometry>
        <mesh
          filename="file://$(find galbot_s1_v1_description)/meshes/Wheel_3_drive_link.STL" />
      </geometry>
      <material name="wheel_material3">
        <color rgba="0.2 0.2 0.2 1"/> 
      </material>
    </visual>
    <collision>
      <origin
        xyz="0 0 0"
        rpy="0 0 0" />
      <geometry>
        <mesh
          filename="file://$(find galbot_s1_v1_description)/meshes/convex_hull/Wheel_3_drive_link_convex_hull.STL" />
      </geometry>
      <geometry>
        <cylinder radius="${wheel_radius}" length="${wheel_length}"/>    
      </geometry>


      <surface>
        <contact>
          <ode>
            <kp>1e7</kp>
            <kd>0.5</kd>
            <max_vel>0.1</max_vel>
            <min_depth>0.001</min_depth>
          </ode>
        </contact>
        <friction>
          <ode>
            <mu>1.2</mu>
            <mu2>1.2</mu2>
          </ode>
        </friction>
      </surface>
    </collision>

  </link>
  <joint
    name="Wheel_3_drive_joint"
    type="continuous">
    <origin
      xyz="0 0 0"
      rpy="-1.5707963267949 0 0" />
    <parent
      link="Wheel_3_direction_link" />
    <child
      link="Wheel_3_drive_link" />
    <axis
      xyz="0 0 1" />
    <limit
      effort="2000"
      velocity="100.0" />
  </joint>
  <link
    name="Wheel_4_direction_link">
    <inertial>
      <origin
        xyz="-0.0002127417129828 -0.0330648318180284 0.0675533979401464"
        rpy="0 0 0" />
      <mass
        value="2.13611778984097" />
      <inertia
        ixx="0.00374225819721817"
        ixy="-8.41639886077924E-06"
        ixz="-2.66657358982123E-05"
        iyy="0.00413405478701947"
        iyz="-0.00111306912741515"
        izz="0.00309941801315196" />
    </inertial>
    <visual>
      <origin
        xyz="0 0 0"
        rpy="0 0 0" />
      <geometry>
        <mesh
          filename="file://$(find galbot_s1_v1_description)/meshes/Wheel_4_direction_link.STL" />
      </geometry>
      <material
        name="">
        <color
          rgba="0.752941176470588 0.752941176470588 0.752941176470588 1" />
      </material>
    </visual>
    <collision>
      <origin
        xyz="0 0 0"
        rpy="0 0 0" />
      <geometry>
        <mesh
          filename="file://$(find galbot_s1_v1_description)/meshes/convex_hull/Wheel_4_direction_link_convex_hull.STL" />
      </geometry>
    </collision>
  </link>
  <joint
    name="Wheel_4_direction_joint"
    type="revolute">
    <origin
      xyz="-0.247 0.247 0.0535000000450749"
      rpy="0 0 0" />
    <parent
      link="base_link" />
    <child
      link="Wheel_4_direction_link" />
    <axis
      xyz="0 0 1" />
    <limit
      lower="-3.14"
      upper="3.14"
      effort="2000"
      velocity="20.0" />
  </joint>
  <link
    name="Wheel_4_drive_link">
    <inertial>
      <origin
        xyz="-0.00045905082180106 -1.71518599521026E-05 -0.000901214993496297"
        rpy="0 0 0" />
      <mass
        value="1.57669100568513" />
      <inertia
        ixx="0.0031621979525809"
        ixy="-3.99825643297236E-06"
        ixz="1.54242222607153E-05"
        iyy="0.00319410118266586"
        iyz="1.91094063018064E-06"
        izz="0.00479196762492548" />
    </inertial>
    <visual>
      <origin
        xyz="0 0 0"
        rpy="0 0 0" />
      <geometry>
        <mesh
          filename="file://$(find galbot_s1_v1_description)/meshes/Wheel_4_drive_link.STL" />
      </geometry>
      <material name="wheel_material4">
        <color rgba="0.2 0.2 0.2 1"/> 
      </material>
    </visual>
    <collision>
      <origin
        xyz="0 0 0"
        rpy="0 0 0" />
      <geometry>
        <mesh
          filename="file://$(find galbot_s1_v1_description)/meshes/convex_hull/Wheel_4_drive_link_convex_hull.STL" />
      </geometry>
      <geometry>
        <cylinder radius="${wheel_radius}" length="${wheel_length}"/>    
      </geometry>

      <surface>
        <contact>
          <ode>
            <kp>1e7</kp>
            <kd>0.5</kd>
            <max_vel>0.1</max_vel>
            <min_depth>0.001</min_depth>
          </ode>
        </contact>
        <friction>
          <ode>
            <mu>1.2</mu>
            <mu2>1.2</mu2>
          </ode>
        </friction>
      </surface>
    </collision>
  </link>
  <joint
    name="Wheel_4_drive_joint"
    type="continuous">
    <origin
      xyz="0 0 0"
      rpy="-1.5707963267949 0 0" />
    <parent
      link="Wheel_4_direction_link" />
    <child
      link="Wheel_4_drive_link" />
    <axis
      xyz="0 0 1" />
    <limit
      effort="2000"
      velocity="100.0" />
  </joint>

  <link
    name="torso_base_link">
    <inertial>
      <origin
        xyz="-0.049697693957585 -0.00115497905905144 0.0904761455432604"
        rpy="0 0 0" />
      <mass
        value="8.48770247940865" />
      <inertia
        ixx="0.0668338255148914"
        ixy="-9.38553737106888E-06"
        ixz="5.25238784045112E-05"
        iyy="0.0300874835718107"
        iyz="-0.00111871025001619"
        izz="0.0499306061349001" />
    </inertial>
    <visual>
      <origin
        xyz="0 0 0"
        rpy="0 0 0" />
      <geometry>
        <mesh
          filename="file://$(find galbot_s1_v1_description)/meshes/torso_base_link.STL" />
      </geometry>
      <material
        name="torso_base_link_material">
        <color
          rgba="1.0 0.415 0.415 1" />
      </material>
    </visual>
    <collision>
      <origin
        xyz="0 0 0"
        rpy="0 0 0" />
      <geometry>
        <mesh
          filename="file://$(find galbot_s1_v1_description)/meshes/convex_hull/torso_base_link_convex_hull.STL" />
      </geometry>
    </collision>
  </link>
  <joint
    name="torso_base_joint"
    type="prismatic">
    <origin
      xyz="0 0 0.0"
      rpy="0 0 0" />
    <parent
      link="column_base_link" />
    <child
      link="torso_base_link" />
    <axis
      xyz="0 0 1" />
    <limit
      lower="0"
      upper="0.75"
      effort="1000"
      velocity="0.5" />
  </joint>
  
  <link
    name="torso_right_arm_amount_link">
    <inertial>
      <origin
        xyz="-0.0029823 -0.067855 -0.26989"
        rpy="0 0 0" />
      <mass
        value="12.044" />
      <inertia
        ixx="0.40636"
        ixy="-0.019013"
        ixz="0.0039866"
        iyy="0.2451"
        iyz="0.034647"
        izz="0.35037" />
    </inertial>
    <visual>
      <origin
        xyz="0 0 0"
        rpy="0 0 0" />
      <geometry>
        <mesh
          filename="file://$(find galbot_s1_v1_description)/meshes/torso_right_arm_amount_link.STL" />
      </geometry> 
      <material
        name="">
        <color
          rgba="1 1 1 1" />
      </material>
    </visual>
  </link>
  <joint
    name="torso_right_arm_amount_joint"
    type="fixed">
    <origin
      xyz="0.0985 -0.28025 0.16659"
      rpy="-1.309 0 3.1416" />
    <parent
      link="torso_base_link" />
    <child
      link="torso_right_arm_amount_link" />
    <axis
      xyz="0 0 0" />
  </joint> 

  <link
    name="torso_left_arm_amount_link">
    <inertial>
      <origin
        xyz="-0.0029823 0.068885 -0.27373"
        rpy="0 0 0" />
      <mass
        value="12.044" />
      <inertia
        ixx="0.40636"
        ixy="0.018459"
        ixz="0.0060541"
        iyy="0.24141"
        iyz="-0.02826"
        izz="0.35406" />
    </inertial>
    <visual>
      <origin
        xyz="0 0 0"
        rpy="0 0 0" />
      <geometry>
        <mesh
          filename="file://$(find galbot_s1_v1_description)/meshes/torso_left_arm_amount_link.STL" />
      </geometry>
      <material
        name="">
        <color
          rgba="1 1 1 1" />
      </material>
    </visual>
    
  </link>
  <joint
    name="torso_left_arm_amount_joint"
    type="fixed">
    <origin
      xyz="0.0985 0.28025 0.16659"
      rpy="1.309 0 3.1416" />
    <parent
      link="torso_base_link" />
    <child
      link="torso_left_arm_amount_link" />
    <axis
      xyz="0 0 0" />
  </joint>

  <link
    name="head_Link1">
    <inertial>
      <origin
        xyz="-0.045396 -0.012681 -0.0032725"
        rpy="0 0 0" />
      <mass
        value="0.33311" />
      <inertia
        ixx="0.00027395"
        ixy="-1.2541E-05"
        ixz="3.4491E-05"
        iyy="0.00031414"
        iyz="7.628E-06"
        izz="0.0003335" />
    </inertial>
    <visual>
      <origin
        xyz="0 0 0"
        rpy="0 0 0" />
      <geometry>
        <mesh
          filename="file://$(find galbot_s1_v1_description)/meshes/head_Link1.STL" />
      </geometry>
      <material
        name="head_Link1_material">
        <color
          rgba="1.0 0.415 0.415 1" />
      </material>
    </visual>
    <collision>
      <origin
        xyz="0 0 0"
        rpy="0 0 0" />
      <geometry>
        <mesh
          filename="file://$(find galbot_s1_v1_description)/meshes/convex_hull/head_Link1_convex_hull.STL" />
      </geometry>
    </collision>
  </link>
  <joint
    name="head_joint1"
    type="fixed">
    <origin
      xyz="0.1145 0 0.29278"
      rpy="0 0 0" />
    <parent
      link="torso_base_link" />
    <child
      link="head_Link1" />
    <axis
      xyz="0 0 1" />
    <limit
      lower="-0.7854"
      upper="0.7854"
      effort="0"
      velocity="0" />
  </joint>
  <link
    name="head_Link2">
    <inertial>
      <origin
        xyz="0.082529 -0.092674 -0.0056067"
        rpy="0 0 0" />
      <mass
        value="0.65299" />
      <inertia
        ixx="0.0023816"
        ixy="9.8473E-05"
        ixz="-0.00011432"
        iyy="0.0018713"
        iyz="0.00022284"
        izz="0.0017889" />
    </inertial>
    <visual>
      <origin
        xyz="0 0 0"
        rpy="0 0 0" />
      <geometry>
        <mesh
          filename="file://$(find galbot_s1_v1_description)/meshes/head_Link2.STL" />
      </geometry>
      <material
        name="head_Link2_material">
        <color
          rgba="1.0 0.415 0.415 1" />
      </material>
    </visual>
    <collision>
      <origin
        xyz="0 0 0"
        rpy="0 0 0" />
      <geometry>
        <mesh
          filename="file://$(find galbot_s1_v1_description)/meshes/convex_hull/head_Link2_convex_hull.STL" />
      </geometry>
    </collision>
  </link>
  <joint
    name="head_joint2"
    type="fixed">
    <origin
      xyz="-0.052556 0 0"
      rpy="-1.5708 0 0" />
    <parent
      link="head_Link1" />
    <child
      link="head_Link2" />
    <axis
      xyz="0 0 1" />
    <limit
      lower="-0.6109"
      upper="0.6109"
      effort="0"
      velocity="0" />
  </joint>

  <joint name="left_arm_base_joint" type="fixed">
    <origin rpy="0 0 0" xyz="0 0 0"/>
    <parent link="torso_left_arm_amount_link"/>
    <child link="left_arm_base_link"/>
  </joint>
  <link
    name="left_arm_base_link">
    <inertial>
      <origin
        xyz="1.2955E-05 -3.6917E-05 -0.18618"
        rpy="0 0 0" />
      <mass
        value="2.0214" />
      <inertia
        ixx="0.0050263"
        ixy="-2.4938E-07"
        ixz="-1.2509E-06"
        iyy="0.0050547"
        iyz="-2.5229E-06"
        izz="0.0053318" />
    </inertial>
    <visual>
      <origin
        xyz="0 0 0"
        rpy="0 0 0" />
      <geometry>
        <mesh
          filename="file://$(find galbot_s1_v1_description)/meshes/S1_left_arm_base_link.STL" />
      </geometry>
      <material
        name="left_arm_base_link_material">
        <color
          rgba="1.0 0.87 0.678 1" />
      </material>
    </visual>
    <collision>
      <origin
        xyz="0 0 0"
        rpy="0 0 0" />
      <geometry>
        <mesh
          filename="file://$(find galbot_s1_v1_description)/meshes/convex_hull/S1_left_arm_base_link_convex_hull.STL" />
      </geometry>
    </collision>
  </link>

  <link
    name="left_arm_link1">
    <inertial>
      <origin
        xyz="-4.4056E-06 0.010421 -0.030155"
        rpy="0 0 0" />
      <mass
        value="1.6782" />
      <inertia
        ixx="0.0041684"
        ixy="-0.00010233"
        ixz="-8.2402E-07"
        iyy="0.0052493"
        iyz="-0.0001273"
        izz="0.0041315" />
    </inertial>
    <visual>
      <origin
        xyz="0 0 0"
        rpy="0 0 0" />
      <geometry>
        <mesh
          filename="file://$(find galbot_s1_v1_description)/meshes/S1_left_arm_link_1.STL" />
      </geometry>
      <material
        name="left_arm_link1_material">
        <color
          rgba="1.0 0.87 0.678 1" />
      </material>
    </visual>
    <collision>
      <origin
        xyz="0 0 0"
        rpy="0 0 0" />
      <geometry>
        <mesh
          filename="file://$(find galbot_s1_v1_description)/meshes/convex_hull/S1_left_arm_link_1_convex_hull.STL" />
      </geometry>
    </collision>
  </link>
  <joint
    name="left_arm_joint1"
    type="fixed">
    <origin
      xyz="0 0 0"
      rpy="0 0 0.5236" />
    <parent
      link="left_arm_base_link" />
    <child
      link="left_arm_link1" />
    <axis
      xyz="0 0 1" />
    <limit
      lower="-2.9671"
      upper="2.9671"
      effort="500"
      velocity="1.0" />
  </joint>
  <link
    name="left_arm_link2">
    <inertial>
      <origin
        xyz="-0.0034501118799037 0.137578949907149 0.000941370679859309"
        rpy="0 0 0" />
      <mass
        value="1.61191175323891" />
      <inertia
        ixx="0.0074618431975222"
        ixy="5.29645480766545E-05"
        ixz="-5.83302388402014E-05"
        iyy="0.00464259274452777"
        iyz="0.00127267735417574"
        izz="0.00647553404817012" />
    </inertial>
    <visual>
      <origin
        xyz="0 0 0"
        rpy="0 0 0" />
      <geometry>
        <mesh
          filename="file://$(find galbot_s1_v1_description)/meshes/S1_left_arm_link_2.STL" />
      </geometry>
      <material
        name="left_arm_link2_material">
        <color
          rgba="1.0 0.87 0.678 1" />
      </material>
    </visual>
    <collision>
      <origin
        xyz="0 0 0"
        rpy="0 0 0" />
      <geometry>
        <mesh
          filename="file://$(find galbot_s1_v1_description)/meshes/convex_hull/S1_left_arm_link_2_convex_hull.STL" />
      </geometry>
    </collision>
  </link>
  <joint
    name="left_arm_joint2"
    type="fixed">
    <origin
      xyz="0 0 0"
      rpy="1.5708 0 3.1416" />
    <parent
      link="left_arm_link1" />
    <child
      link="left_arm_link2" />
    <axis
      xyz="0 0 1" />
    <limit
      lower="-3.14"
      upper="3.14"
      effort="500"
      velocity="1.0" />
  </joint>
  <link
    name="left_arm_link3">
    <inertial>
      <origin
        xyz="0.0055631 0.0047021 -0.073122"
        rpy="0 0 0" />
      <mass
        value="1.5708" />
      <inertia
        ixx="0.0062978"
        ixy="-6.4139E-06"
        ixz="0.00019319"
        iyy="0.0067717"
        iyz="-0.00024069"
        izz="0.002835" />
    </inertial>
    <visual>
      <origin
        xyz="0 0 0"
        rpy="0 0 0" />
      <geometry>
        <mesh
          filename="file://$(find galbot_s1_v1_description)/meshes/S1_left_arm_link_3.STL" />
      </geometry>
      <material
        name="left_arm_link3_material">
        <color
          rgba="1.0 0.87 0.678 1" />
      </material>
    </visual>
    <collision>
      <origin
        xyz="0 0 0"
        rpy="0 0 0" />
      <geometry>
        <mesh
          filename="file://$(find galbot_s1_v1_description)/meshes/convex_hull/S1_left_arm_link_3_convex_hull.STL" />
      </geometry>
    </collision>
  </link>
  <joint
    name="left_arm_joint3"
    type="fixed">
    <origin
      xyz="0 0.49 0"
      rpy="1.5708 1.0472 3.1416" />
    <parent
      link="left_arm_link2" />
    <child
      link="left_arm_link3" />
    <axis
      xyz="0 0 1" />
    <limit
      lower="-3.14"
      upper="3.14"
      effort="300"
      velocity="1.0" />
  </joint>
  <link
    name="left_arm_link4">
    <inertial>
      <origin
        xyz="-3.8512E-06 -0.10045 0.0022227"
        rpy="0 0 0" />
      <mass
        value="0.8579" />
      <inertia
        ixx="0.0025792"
        ixy="-3.9535E-07"
        ixz="4.94E-07"
        iyy="0.0016987"
        iyz="-0.00043511"
        izz="0.0021546" />
    </inertial>
    <visual>
      <origin
        xyz="0 0 0"
        rpy="0 0 0" />
      <geometry>
        <mesh
          filename="file://$(find galbot_s1_v1_description)/meshes/S1_left_arm_link_4.STL" />
      </geometry>
      <material
        name="left_arm_link4_material">
        <color
          rgba="1.0 0.87 0.678 1" />
      </material>
    </visual>
    <collision>
      <origin
        xyz="0 0 0"
        rpy="0 0 0" />
      <geometry>
        <mesh
          filename="file://$(find galbot_s1_v1_description)/meshes/convex_hull/S1_left_arm_link_4_convex_hull.STL" />
      </geometry>
    </collision>
  </link>
  <joint
    name="left_arm_joint4"
    type="fixed">
    <origin
      xyz="0 0 0"
      rpy="-1.5708 0 0" />
    <parent
      link="left_arm_link3" />
    <child
      link="left_arm_link4" />
    <axis
      xyz="0 0 1" />
    <limit
      lower="-3.14"
      upper="3.14"
      effort="300"
      velocity="1.0" />
  </joint>

  <link
    name="left_arm_link5">
    <inertial>
      <origin
        xyz="0.00120100061366775 0.00724301174795389 -0.15375870300824"
        rpy="0 0 0" />
      <mass
        value="0.856081132239411" />
      <inertia
        ixx="0.00204386493977559"
        ixy="6.25579448909938E-06"
        ixz="1.11817133453669E-05"
        iyy="0.00188725719398212"
        iyz="-0.000218840009334318"
        izz="0.000992021147911612" />
    </inertial>
    <visual>
      <origin
        xyz="0 0 0"
        rpy="0 0 0" />
      <geometry>
        <mesh
          filename="file://$(find galbot_s1_v1_description)/meshes/S1_left_arm_link_5.STL" />
      </geometry>
      <material
        name="left_arm_link5_material">
        <color
          rgba="1.0 0.87 0.678 1" />
      </material>
    </visual>
    <collision>
      <origin
        xyz="0 0 0"
        rpy="0 0 0" />
      <geometry>
        <mesh
          filename="file://$(find galbot_s1_v1_description)/meshes/convex_hull/S1_left_arm_link_5_convex_hull.STL" />
      </geometry>
    </collision>
  </link>
  <joint
    name="left_arm_joint5"
    type="fixed">
    <origin
      xyz="0 -0.4307 4.6056E-05"
      rpy="-1.5708 0 -3.1416" />
    <parent
      link="left_arm_link4" />
    <child
      link="left_arm_link5" />
    <axis
      xyz="0 0 1" />
    <limit
      lower="-3.14"
      upper="3.14"
      effort="300"
      velocity="1.0" />
  </joint>
  <link
    name="left_arm_link6">
    <inertial>
      <origin
        xyz="0.000205952998414416 -0.00495236167031805 3.84411081668564E-05"
        rpy="0 0 0" />
      <mass
        value="0.405314378809454" />
      <inertia
        ixx="0.000384854292305239"
        ixy="-6.3461265357739E-07"
        ixz="3.02626882407001E-06"
        iyy="0.000441984987804781"
        iyz="-2.73448533483226E-06"
        izz="0.000376660901136125" />
    </inertial>
    <visual>
      <origin
        xyz="0 0 0"
        rpy="0 0 0" />
      <geometry>
        <mesh
          filename="file://$(find galbot_s1_v1_description)/meshes/S1_left_arm_link_6.STL" />
      </geometry>
      <material
        name="left_arm_link6_material">
        <color
          rgba="1.0 0.87 0.678 1" />
      </material>
    </visual>
    <collision>
      <origin
        xyz="0 0 0"
        rpy="0 0 0" />
      <geometry>
        <mesh
          filename="file://$(find galbot_s1_v1_description)/meshes/convex_hull/S1_left_arm_link_6_convex_hull.STL" />
      </geometry>
    </collision>
  </link>
  <joint
    name="left_arm_joint6"
    type="fixed">
    <origin
      xyz="0 0 0"
      rpy="-1.5708 -1.5708 0" />
    <parent
      link="left_arm_link5" />
    <child
      link="left_arm_link6" />
    <axis
      xyz="0 0 1" />
    <limit
      lower="-3.14"
      upper="3.14"
      effort="300"
      velocity="1.0" />
  </joint>
  <link
    name="left_arm_link7">
    <inertial>
      <origin
        xyz="-0.0897462313068071 0.0110171804587007 0.0187556758389912"
        rpy="0 0 0" />
      <mass
        value="0.341970858699489" />
      <inertia
        ixx="0.000279067842250059"
        ixy="-8.14227980518424E-07"
        ixz="-7.76397833743042E-05"
        iyy="0.000415635269304694"
        iyz="-3.01302151574681E-06"
        izz="0.000371118069134061" />
    </inertial>
    <visual>
      <origin
        xyz="0 0 0"
        rpy="0 0 0" />
      <geometry>
        <mesh
          filename="file://$(find galbot_s1_v1_description)/meshes/S1_left_arm_link_7.STL" />
      </geometry>
      <material
        name="left_arm_link7_material">
        <color
          rgba="1.0 0.87 0.678 1" />
      </material>
    </visual>
    <collision>
      <origin
        xyz="0 0 0"
        rpy="0 0 0" />
      <geometry>
        <mesh
          filename="file://$(find galbot_s1_v1_description)/meshes/convex_hull/S1_left_arm_link_7_convex_hull.STL" />
      </geometry>
    </collision>
  </link>
  <joint
    name="left_arm_joint7"
    type="fixed">
    <origin
      xyz="0 0 0"
      rpy="-1.5708 0 -3.1416" />
    <parent
      link="left_arm_link6" />
    <child
      link="left_arm_link7" />
    <axis
      xyz="0 0 1" />
    <limit
      lower="-3.14"
      upper="3.14"
      effort="100"
      velocity="1.0" />
  </joint>

  <joint name="right_arm_base_joint" type="fixed">
    <origin rpy="0 0 0" xyz="0 0 0"/>
    <parent link="torso_right_arm_amount_link"/>
    <child link="right_arm_base_link"/>
  </joint>
  <link
    name="right_arm_base_link">
    <inertial>
      <origin
        xyz="-1.29552206996727E-05 3.69172827554587E-05 -0.186181097520521"
        rpy="0 0 0" />
      <mass
        value="2.02135129237826" />
      <inertia
        ixx="0.00502630358338234"
        ixy="-2.49381654319174E-07"
        ixz="1.25088698000314E-06"
        iyy="0.00505468118499986"
        iyz="2.52292665925089E-06"
        izz="0.00533182616848263" />
    </inertial>
    <visual>
      <origin
        xyz="0 0 0"
        rpy="0 0 0" />
      <geometry>
        <mesh
          filename="file://$(find galbot_s1_v1_description)/meshes/S1_right_arm_base_link.STL" />
      </geometry>
      <material
        name="right_arm_base_link_material">
        <color
          rgba="1.0 0.87 0.678 1" />
      </material>
    </visual>
    <collision>
      <origin
        xyz="0 0 0"
        rpy="0 0 0" />
      <geometry>
        <mesh
          filename="file://$(find galbot_s1_v1_description)/meshes/convex_hull/S1_right_arm_base_link_convex_hull.STL" />
      </geometry>
    </collision>
  </link>
  
  <link
    name="right_arm_link1">
    <inertial>
      <origin
        xyz="4.41589397874959E-06 -0.0104207411701647 -0.0301548913491024"
        rpy="0 0 0" />
      <mass
        value="1.67818884758122" />
      <inertia
        ixx="0.00416840723974718"
        ixy="-0.000102327621451166"
        ixz="8.23905011691609E-07"
        iyy="0.00524928393137641"
        iyz="0.000127305160373526"
        izz="0.00413151101917077" />
    </inertial>
    <visual>
      <origin
        xyz="0 0 0"
        rpy="0 0 0" />
      <geometry>
        <mesh
          filename="file://$(find galbot_s1_v1_description)/meshes/S1_right_arm_link_1.STL" />
      </geometry>
      <material
        name="right_arm_link1_material">
        <color
          rgba="1.0 0.87 0.678 1" />
      </material>
    </visual>
    <collision>
      <origin
        xyz="0 0 0"
        rpy="0 0 0" />
      <geometry>
        <mesh
          filename="file://$(find galbot_s1_v1_description)/meshes/convex_hull/S1_right_arm_link_1_convex_hull.STL" />
      </geometry>
    </collision>
  </link>
  <joint
    name="right_arm_joint1"
    type="fixed">
    <origin
      xyz="0 0 0"
      rpy="0 0 -0.5236" />
    <parent
      link="right_arm_base_link" />
    <child
      link="right_arm_link1" />
    <axis
      xyz="0 0 1" />
    <limit
      lower="-3.14"
      upper="3.14"
      effort="500"
      velocity="1.0" />
  </joint>

  <link
    name="right_arm_link2">
    <inertial>
      <origin
        xyz="-0.00339442501847311 -0.137566658938318 0.00100731759706021"
        rpy="0 0 0" />
      <mass
        value="1.61262054749791" />
      <inertia
        ixx="0.0074606447755588"
        ixy="-5.32977799230042E-05"
        ixz="-5.98917449710725E-05"
        iyy="0.00464249559485519"
        iyz="-0.00127297723288935"
        izz="0.00647608669810105" />
    </inertial>
    <visual>
      <origin
        xyz="0 0 0"
        rpy="0 0 0" />
      <geometry>
        <mesh
          filename="file://$(find galbot_s1_v1_description)/meshes/S1_right_arm_link_2.STL" />
      </geometry>
      <material
        name="right_arm_link2_material">
        <color
          rgba="1.0 0.87 0.678 1" />
      </material>
    </visual>
    <collision>
      <origin
        xyz="0 0 0"
        rpy="0 0 0" />
      <geometry>
        <mesh
          filename="file://$(find galbot_s1_v1_description)/meshes/convex_hull/S1_right_arm_link_2_convex_hull.STL" />
      </geometry>
    </collision>
  </link>
  <joint
    name="right_arm_joint2"
    type="fixed">
    <origin
      xyz="0 0 0"
      rpy="-1.5708 0 3.1416" />
    <parent
      link="right_arm_link1" />
    <child
      link="right_arm_link2" />
    <axis
      xyz="0 0 1" />
    <limit
      lower="-3.14"
      upper="3.14"
      effort="500"
      velocity="1.0" />
  </joint>

  <link
    name="right_arm_link3">
    <inertial>
      <origin
        xyz="0.00559843643162938 -0.00496183803578002 -0.0733741183680984"
        rpy="0 0 0" />
      <mass
        value="1.58036268590667" />
      <inertia
        ixx="0.00634185118145533"
        ixy="2.93823130628494E-06"
        ixz="0.000194380753796057"
        iyy="0.0067768127028596"
        iyz="0.00022856666210439"
        izz="0.00285386553458627" />
    </inertial>
    <visual>
      <origin
        xyz="0 0 0"
        rpy="0 0 0" />
      <geometry>
        <mesh
          filename="file://$(find galbot_s1_v1_description)/meshes/S1_right_arm_link_3.STL" />
      </geometry>
      <material
        name="right_arm_link3_material">
        <color
          rgba="1.0 0.87 0.678 1" />
      </material>
    </visual>
    <collision>
      <origin
        xyz="0 0 0"
        rpy="0 0 0" />
      <geometry>
        <mesh
          filename="file://$(find galbot_s1_v1_description)/meshes/convex_hull/S1_right_arm_link_3_convex_hull.STL" />
      </geometry>
    </collision>
  </link>
  <joint
    name="right_arm_joint3"
    type="fixed">
    <origin
      xyz="0 -0.49 0"
      rpy="-1.5708 1.0472 3.1416" />
    <parent
      link="right_arm_link2" />
    <child
      link="right_arm_link3" />
    <axis
      xyz="0 0 1" />
    <limit
      lower="-3.14"
      upper="3.14"
      effort="300"
      velocity="1.0" />
  </joint>

  <link
    name="right_arm_link4">
    <inertial>
      <origin
        xyz="3.1137217060871E-06 0.100449531137548 0.00222271249348109"
        rpy="0 0 0" />
      <mass
        value="0.857836804313015" />
      <inertia
        ixx="0.00257913167487251"
        ixy="-4.29152869719467E-07"
        ixz="-4.39435112832358E-07"
        iyy="0.00169863598130374"
        iyz="0.000435107495449623"
        izz="0.00215455515090187" />
    </inertial>
    <visual>
      <origin
        xyz="0 0 0"
        rpy="0 0 0" />
      <geometry>
        <mesh
          filename="file://$(find galbot_s1_v1_description)/meshes/S1_right_arm_link_4.STL" />
      </geometry>
      <material
        name="right_arm_link4_material">
        <color
          rgba="1.0 0.87 0.678 1" />
      </material>
    </visual>
    <collision>
      <origin
        xyz="0 0 0"
        rpy="0 0 0" />
      <geometry>
        <mesh
          filename="file://$(find galbot_s1_v1_description)/meshes/convex_hull/S1_right_arm_link_4_convex_hull.STL" />
      </geometry>
    </collision>
  </link>
  <joint
    name="right_arm_joint4"
    type="fixed">
    <origin
      xyz="0 0 0"
      rpy="1.5708 0 0" />
    <parent
      link="right_arm_link3" />
    <child
      link="right_arm_link4" />
    <axis
      xyz="0 0 1" />
    <limit
      lower="-3.14"
      upper="3.14"
      effort="300"
      velocity="1.0" />
  </joint>
  <link
    name="right_arm_link5">
    <inertial>
      <origin
        xyz="-0.00122679554310865 0.00731018781948563 -0.152851503118004"
        rpy="0 0 0" />
      <mass
        value="0.862471836244391" />
      <inertia
        ixx="0.00204311460907629"
        ixy="-4.655773880675E-06"
        ixz="-1.18604374690496E-05"
        iyy="0.00188766982179655"
        iyz="-0.000219076240837255"
        izz="0.000993243125871473" />
    </inertial>
    <visual>
      <origin
        xyz="0 0 0"
        rpy="0 0 0" />
      <geometry>
        <mesh
          filename="file://$(find galbot_s1_v1_description)/meshes/S1_right_arm_link_5.STL" />
      </geometry>
      <material
        name="right_arm_link5_material">
        <color
          rgba="1.0 0.87 0.678 1" />
      </material>
    </visual>
    <collision>
      <origin
        xyz="0 0 0"
        rpy="0 0 0" />
      <geometry>
        <mesh
          filename="file://$(find galbot_s1_v1_description)/meshes/convex_hull/S1_right_arm_link_5_convex_hull.STL" />
      </geometry>
    </collision>
  </link>
  <joint
    name="right_arm_joint5"
    type="fixed">
    <origin
      xyz="0 0.43072 4.6056E-05"
      rpy="-1.5708 0 0" />
    <parent
      link="right_arm_link4" />
    <child
      link="right_arm_link5" />
    <axis
      xyz="0 0 1" />
    <limit
      lower="-3.14"
      upper="3.14"
      effort="300"
      velocity="1.0" />
  </joint>

  <link
    name="right_arm_link6">
    <inertial>
      <origin
        xyz="0.000237711148310504 0.00500175113098505 0.000203337227847911"
        rpy="0 0 0" />
      <mass
        value="0.401237573301889" />
      <inertia
        ixx="0.000384725033614958"
        ixy="6.76254417690832E-07"
        ixz="3.41044660623136E-06"
        iyy="0.000441789726991694"
        iyz="3.31974415372349E-06"
        izz="0.000376227616178077" />
    </inertial>
    <visual>
      <origin
        xyz="0 0 0"
        rpy="0 0 0" />
      <geometry>
        <mesh
          filename="file://$(find galbot_s1_v1_description)/meshes/S1_right_arm_link_6.STL" />
      </geometry>
      <material
        name="right_arm_link6_material">
        <color
          rgba="1.0 0.87 0.678 1" />
      </material>
    </visual>
    <collision>
      <origin
        xyz="0 0 0"
        rpy="0 0 0" />
      <geometry>
        <mesh
          filename="file://$(find galbot_s1_v1_description)/meshes/convex_hull/S1_right_arm_link_6_convex_hull.STL" />
      </geometry>
    </collision>
  </link>
  <joint
    name="right_arm_joint6"
    type="fixed">
    <origin
      xyz="0 0 0"
      rpy="-1.5708 -1.5708 0" />
    <parent
      link="right_arm_link5" />
    <child
      link="right_arm_link6" />
    <axis
      xyz="0 0 1" />
    <limit
      lower="-3.14"
      upper="3.14"
      effort="300"
      velocity="1.0" />
  </joint>
  <link
    name="right_arm_link7">
    <inertial>
      <origin
        xyz="-0.0898814826798238 -0.0110675020738209 0.0187479617354055"
        rpy="0 0 0" />
      <mass
        value="0.344021308559621" />
      <inertia
        ixx="0.000279126168292752"
        ixy="8.2812817122701E-07"
        ixz="-7.76890188876959E-05"
        iyy="0.000415959658064511"
        iyz="2.96898769106739E-06"
        izz="0.000371648160842017" />
    </inertial>
    <visual>
      <origin
        xyz="0 0 0"
        rpy="0 0 0" />
      <geometry>
        <mesh
          filename="file://$(find galbot_s1_v1_description)/meshes/S1_right_arm_link_7.STL" />
      </geometry>
      <material
        name="right_arm_link7_material">
        <color
          rgba="1.0 0.87 0.678 1" />
      </material>
    </visual>
    <collision>
      <origin
        xyz="0 0 0"
        rpy="0 0 0" />
      <geometry>
        <mesh
          filename="file://$(find galbot_s1_v1_description)/meshes/convex_hull/S1_right_arm_link_7_convex_hull.STL" />
      </geometry>
    </collision>
  </link>
  <joint
    name="right_arm_joint7"
    type="fixed">
    <origin
      xyz="0 0 0"
      rpy="1.5708 0 3.1416" />
    <parent
      link="right_arm_link6" />
    <child
      link="right_arm_link7" />
    <axis
      xyz="0 0 1" />
    <limit
      lower="-3.14"
      upper="3.14"
      effort="100"
      velocity="1.0" />
  </joint>

  <!-- Gazebo Control -->
  <ros2_control name="control" type="system">
    <hardware>
      <plugin>gz_ros2_control/GazeboSimSystem</plugin>
    </hardware>
          
    <joint name="Wheel_1_direction_joint">
      <command_interface name="position">
        <param name="min">-3.14</param>
        <param name="max">3.14</param>
      </command_interface>

      <state_interface name="position"/>
      <state_interface name="velocity"/>
      <state_interface name="effort"/>
    </joint>

    <joint name="Wheel_2_direction_joint">
      <command_interface name="position">
        <param name="min">-3.14</param>
        <param name="max">3.14</param>
      </command_interface>

      <state_interface name="position"/>
      <state_interface name="velocity"/>
      <state_interface name="effort"/>
    </joint>

    <joint name="Wheel_3_direction_joint">
      <command_interface name="position">
        <param name="min">-3.14</param>
        <param name="max">3.14</param>
      </command_interface>
      <state_interface name="position"/>
      <state_interface name="velocity"/>
      <state_interface name="effort"/>
    </joint>

    <joint name="Wheel_4_direction_joint">
      <command_interface name="position">
        <param name="min">-3.14</param>
        <param name="max">3.14</param>
      </command_interface>
      <state_interface name="position"/>
      <state_interface name="velocity"/>
      <state_interface name="effort"/>
    </joint>

    <joint name="Wheel_1_drive_joint">
      <command_interface name="velocity">
        <param name="min">-3.14</param>
        <param name="max">3.14</param>
      </command_interface>

      <state_interface name="position"/>
      <state_interface name="velocity"/>
      <state_interface name="effort"/>
    </joint>

    <joint name="Wheel_2_drive_joint">
      <command_interface name="velocity">
        <param name="min">-3.14</param>
        <param name="max">3.14</param>
      </command_interface>

      <state_interface name="position"/>
      <state_interface name="velocity"/>
      <state_interface name="effort"/>
    </joint>

    <joint name="Wheel_3_drive_joint">
      <command_interface name="velocity">
        <param name="min">-3.14</param>
        <param name="max">3.14</param>
      </command_interface>

      <state_interface name="position"/>
      <state_interface name="velocity"/>
      <state_interface name="effort"/>
    </joint>

    <joint name="Wheel_4_drive_joint">
      <command_interface name="velocity">
        <param name="min">-3.14</param>
        <param name="max">3.14</param>
      </command_interface>

      <state_interface name="position"/>
      <state_interface name="velocity"/>
      <state_interface name="effort"/>
    </joint>

    <joint name="torso_base_joint">
      <command_interface name="position">
        <param name="min">0</param>
        <param name="max">0.75</param>
      </command_interface>
      <state_interface name="position"/>
      <state_interface name="velocity"/>
      <state_interface name="effort"/>
    </joint>
    
    <joint name="head_joint1">
      <command_interface name="position">
        <param name="min">-3.14</param>
        <param name="max">3.14</param>
      </command_interface>
      <state_interface name="position"/>
      <state_interface name="velocity"/>
      <state_interface name="effort"/>
    </joint>

    <joint name="head_joint2">
      <command_interface name="position">
        <param name="min">-3.14</param>
        <param name="max">3.14</param>
      </command_interface>
      <state_interface name="position"/>
      <state_interface name="velocity"/>
      <state_interface name="effort"/>
    </joint>

    <joint name="left_arm_joint1">
      <command_interface name="position">
        <param name="min">-3.14</param>
        <param name="max">3.14</param>
      </command_interface>
      <state_interface name="position"/>
      <state_interface name="velocity"/>
      <state_interface name="effort"/>
    </joint>

    <joint name="left_arm_joint2">
      <command_interface name="position">
        <param name="min">-3.14</param>
        <param name="max">3.14</param>
      </command_interface>
      <state_interface name="position"/>
      <state_interface name="velocity"/>
      <state_interface name="effort"/>
    </joint>

    <joint name="left_arm_joint3">
      <command_interface name="position">
        <param name="min">-3.14</param>
        <param name="max">3.14</param>
      </command_interface>
      <state_interface name="position"/>
      <state_interface name="velocity"/>
      <state_interface name="effort"/>
    </joint>

    <joint name="left_arm_joint4">
      <command_interface name="position">
        <param name="min">-3.14</param>
        <param name="max">3.14</param>
      </command_interface>
      <state_interface name="position"/>
      <state_interface name="velocity"/>
      <state_interface name="effort"/>
    </joint>

    <joint name="left_arm_joint5">
      <command_interface name="position">
        <param name="min">-3.14</param>
        <param name="max">3.14</param>
      </command_interface>
      <state_interface name="position"/>
      <state_interface name="velocity"/>
      <state_interface name="effort"/>
    </joint>

    <joint name="left_arm_joint6">
      <command_interface name="position">
        <param name="min">-3.14</param>
        <param name="max">3.14</param>
      </command_interface>
      <state_interface name="position"/>
      <state_interface name="velocity"/>
      <state_interface name="effort"/>
    </joint>

    <joint name="left_arm_joint7">
      <command_interface name="position">
        <param name="min">-3.14</param>
        <param name="max">3.14</param>
      </command_interface>
      <state_interface name="position"/>
      <state_interface name="velocity"/>
      <state_interface name="effort"/>
    </joint>

    <joint name="right_arm_joint1">
      <command_interface name="position">
        <param name="min">-3.14</param>
        <param name="max">3.14</param>
      </command_interface>
      <state_interface name="position"/>
      <state_interface name="velocity"/>
      <state_interface name="effort"/>
    </joint>

    <joint name="right_arm_joint2">
      <command_interface name="position">
        <param name="min">-3.14</param>
        <param name="max">3.14</param>
      </command_interface>
      <state_interface name="position"/>
      <state_interface name="velocity"/>
      <state_interface name="effort"/>
    </joint>

    <joint name="right_arm_joint3">
      <command_interface name="position">
        <param name="min">-3.14</param>
        <param name="max">3.14</param>
      </command_interface>
      <state_interface name="position"/>
      <state_interface name="velocity"/>
      <state_interface name="effort"/>
    </joint>

    <joint name="right_arm_joint4">
      <command_interface name="position">
        <param name="min">-3.14</param>
        <param name="max">3.14</param>
      </command_interface>
      <state_interface name="position"/>
      <state_interface name="velocity"/>
      <state_interface name="effort"/>
    </joint>

    <joint name="right_arm_joint5">
      <command_interface name="position">
        <param name="min">-3.14</param>
        <param name="max">3.14</param>
      </command_interface>
      <state_interface name="position"/>
      <state_interface name="velocity"/>
      <state_interface name="effort"/>
    </joint>

    <joint name="right_arm_joint6">
      <command_interface name="position">
        <param name="min">-3.14</param>
        <param name="max">3.14</param>
      </command_interface>
      <state_interface name="position"/>
      <state_interface name="velocity"/>
      <state_interface name="effort"/>
    </joint>

    <joint name="right_arm_joint7">
      <command_interface name="position">
        <param name="min">-3.14</param>
        <param name="max">3.14</param>
      </command_interface>
      <state_interface name="position"/>
      <state_interface name="velocity"/>
      <state_interface name="effort"/>
    </joint>
  </ros2_control>

  <!--sensor 组件-->
<gazebo reference="imu_link">
    <gravity>true</gravity>
    <sensor name="imu_sensor" type="imu">
      <always_on>true</always_on>
      <update_rate>50</update_rate>
      <visualize>true</visualize>
      <topic>__default_topic__</topic>
      
      <plugin filename="libgazebo_ros_imu_sensor.so" name="imu_plugin">
        <topicName>imu</topicName>
        <bodyName>imu_link</bodyName>
        <updateRateHZ>50.0</updateRateHZ>
        <gaussianNoise>0.0</gaussianNoise>
        <xyzOffset>0 0 0</xyzOffset>
        <rpyOffset>0 0 0</rpyOffset>
        <frameName>imu_link</frameName>
        <initialOrientationAsReference>false</initialOrientationAsReference>
      </plugin>
      
      <pose>0 0 0 0 0 0</pose>
    </sensor>
  </gazebo>

<gazebo reference="scan_link">
    <sensor type="ray" name="lidar_sensor">
      <pose>0 0 0 0 0 0</pose>
      <visualize>true</visualize>
      <update_rate>10</update_rate>
      
      <ray>
        <scan>
          <horizontal>
            <samples>720</samples>
            <resolution>1</resolution>
            <min_angle>-3.14156</min_angle>
            <max_angle>3.14156</max_angle>
          </horizontal>
          <vertical>
              <samples>32</samples>
              <resolution>1</resolution>
              <min_angle>-0.5353</min_angle>
              <max_angle>0.1862</max_angle>
          </vertical>
        </scan>
        <range>
          <min>0.05</min>
          <max>10.0</max>
          <resolution>0.01</resolution>
        </range>
        <noise>
            <type>gaussian</type>
            <mean>0.0</mean>
            <stddev>0.01</stddev>
        </noise>
      </ray>

      <plugin name="gazebo_ros_lidar_controller" filename="libgazebo_ros_velodyne_laser.so">
        <topicName>scan</topicName>
        <frameName>scan_link</frameName>
        <min_range>0.05</min_range>
        <max_range>10.0</max_range>
        <gaussianNoise>0.008</gaussianNoise>
      </plugin>
    </sensor>
  </gazebo>
  <!-- Gazebo Plugins -->
<gazebo>
  <plugin name="ground_truth_odometry" filename="libgazebo_ros_p3d.so">
      <alwaysOn>true</alwaysOn>
      <updateRate>50.0</updateRate>
      <bodyName>base_link</bodyName>
      <topicName>odom</topicName>
      <gaussianNoise>0.0</gaussianNoise>
      <frameName>world</frameName>
      <xyzOffsets>0 0 0</xyzOffsets>
      <rpyOffsets>0 0 0</rpyOffsets>
  </plugin>

  <plugin name="gazebo_ros_control" filename="libgazebo_ros_control.so">
    <robotNamespace>/</robotNamespace>
  </plugin>
</gazebo>

  <!-- 舵角 transmission -->
<transmission name="wheel1_steer_trans">
  <type>transmission_interface/SimpleTransmission</type>
  <joint name="Wheel_1_direction_joint">
    <hardwareInterface>hardware_interface/PositionJointInterface</hardwareInterface>
  </joint>
  <actuator name="wheel1_steer_motor">
    <hardwareInterface>hardware_interface/PositionJointInterface</hardwareInterface>
    <mechanicalReduction>1</mechanicalReduction>
  </actuator>
</transmission>

<transmission name="wheel2_steer_trans">
  <type>transmission_interface/SimpleTransmission</type>
  <joint name="Wheel_2_direction_joint">
    <hardwareInterface>hardware_interface/PositionJointInterface</hardwareInterface>
  </joint>
  <actuator name="wheel2_steer_motor">
    <hardwareInterface>hardware_interface/PositionJointInterface</hardwareInterface>
    <mechanicalReduction>1</mechanicalReduction>
  </actuator>
</transmission>

<transmission name="wheel3_steer_trans">
  <type>transmission_interface/SimpleTransmission</type>
  <joint name="Wheel_3_direction_joint">
    <hardwareInterface>hardware_interface/PositionJointInterface</hardwareInterface>
  </joint>
  <actuator name="wheel3_steer_motor">
    <hardwareInterface>hardware_interface/PositionJointInterface</hardwareInterface>
    <mechanicalReduction>1</mechanicalReduction>
  </actuator>
</transmission>

<transmission name="wheel4_steer_trans">
  <type>transmission_interface/SimpleTransmission</type>
  <joint name="Wheel_4_direction_joint">
    <hardwareInterface>hardware_interface/PositionJointInterface</hardwareInterface>
  </joint>
  <actuator name="wheel4_steer_motor">
    <hardwareInterface>hardware_interface/PositionJointInterface</hardwareInterface>
    <mechanicalReduction>1</mechanicalReduction>
  </actuator>
</transmission>

<!-- 轮毂 transmission -->
<transmission name="wheel1_drive_trans">
  <type>transmission_interface/SimpleTransmission</type>
  <joint name="Wheel_1_drive_joint">
    <hardwareInterface>hardware_interface/VelocityJointInterface</hardwareInterface>
  </joint>
  <actuator name="wheel1_drive_motor">
    <hardwareInterface>hardware_interface/VelocityJointInterface</hardwareInterface>
    <mechanicalReduction>1</mechanicalReduction>
  </actuator>
</transmission>

<transmission name="wheel2_drive_trans">
  <type>transmission_interface/SimpleTransmission</type>
  <joint name="Wheel_2_drive_joint">
    <hardwareInterface>hardware_interface/VelocityJointInterface</hardwareInterface>
  </joint>
  <actuator name="wheel2_drive_motor">
    <hardwareInterface>hardware_interface/VelocityJointInterface</hardwareInterface>
    <mechanicalReduction>1</mechanicalReduction>
  </actuator>
</transmission>

<transmission name="wheel3_drive_trans">
  <type>transmission_interface/SimpleTransmission</type>
  <joint name="Wheel_3_drive_joint">
    <hardwareInterface>hardware_interface/VelocityJointInterface</hardwareInterface>
  </joint>
  <actuator name="wheel3_drive_motor">
    <hardwareInterface>hardware_interface/VelocityJointInterface</hardwareInterface>
    <mechanicalReduction>1</mechanicalReduction>
  </actuator>
</transmission>

<transmission name="wheel4_drive_trans">
  <type>transmission_interface/SimpleTransmission</type>
  <joint name="Wheel_4_drive_joint">
    <hardwareInterface>hardware_interface/VelocityJointInterface</hardwareInterface>
  </joint>
  <actuator name="wheel4_drive_motor">
    <hardwareInterface>hardware_interface/VelocityJointInterface</hardwareInterface>
    <mechanicalReduction>1</mechanicalReduction>
  </actuator>
</transmission>

</robot>
